{"uuid": "322d832f-86b7-457d-80f0-d8c46a315fbd", "children": ["dc883072-6059-4128-8da1-c99b9fe73662"], "befores": [{"name": "get_token", "status": "broken", "statusDetails": {"message": "requests.exceptions.ConnectionError: HTTPConnectionPool(host='124.70.94.252', port=8000): Max retries exceeded with url: /api/admin/login (Caused by NewConnectionError('<urllib3.connection.HTTPConnection object at 0x0000020B12C6C040>: Failed to establish a new connection: [WinError 10060] 由于连接方在一段时间后没有正确答复或连接的主机没有反应，连接尝试失败。'))\n", "trace": "  File \"E:\\python\\lib\\site-packages\\pluggy\\_callers.py\", line 39, in _multicall\n    res = hook_impl.function(*args)\n  File \"E:\\python\\lib\\site-packages\\_pytest\\fixtures.py\", line 1126, in pytest_fixture_setup\n    result = call_fixture_func(fixturefunc, request, kwargs)\n  File \"E:\\python\\lib\\site-packages\\_pytest\\fixtures.py\", line 932, in call_fixture_func\n    fixture_result = fixturefunc(**kwargs)\n  File \"E:\\zrlogAutotest\\testcase\\conftest.py\", line 10, in get_token\n    res = requests.post(url=url,json=data,headers=header)\n  File \"E:\\python\\lib\\site-packages\\requests\\api.py\", line 117, in post\n    return request('post', url, data=data, json=json, **kwargs)\n  File \"E:\\python\\lib\\site-packages\\requests\\api.py\", line 61, in request\n    return session.request(method=method, url=url, **kwargs)\n  File \"E:\\python\\lib\\site-packages\\requests\\sessions.py\", line 529, in request\n    resp = self.send(prep, **send_kwargs)\n  File \"E:\\python\\lib\\site-packages\\requests\\sessions.py\", line 645, in send\n    r = adapter.send(request, **kwargs)\n  File \"E:\\python\\lib\\site-packages\\requests\\adapters.py\", line 519, in send\n    raise ConnectionError(e, request=request)\n"}, "start": 1659601000950, "stop": 1659601021956}], "start": 1659601000950, "stop": 1659601022357}